<?xml version="1.0"?>
<robot name="robot_base_respondable">
    <link name="robot_base">
        <collision name="robot_base_respondable">
            <origin xyz="0.000000 -0.000000 0.008500" rpy="3.141592 3.141593 -2.552481" />
            <geometry>
                <cylinder length="0.012300089001656" radius="0.056886240839958" />
            </geometry>
        </collision>
        <collision name="robot_base_respondable">
            <origin xyz="0.000000 -0.000000 -0.006150" rpy="-3.141592 3.141593 1.747927" />
            <geometry>
                <cylinder length="0.017000352963805" radius="0.072642646729946" />
            </geometry>
        </collision>
        <visual name="robot_base_visual">
            <origin xyz="0.000000 -0.000000 0.000000" rpy="3.141592 3.141593 3.141592" />
            <geometry>
                <mesh filename="models/urdf/ur5_closed_robotiq_alpha_oriented/ur5_closed_robotiq_alpha_oriented_robot_base_visual_vis_1.dae" />
            </geometry>
            <material name="robot_base_visual_material">
                <color rgba="0.870588 0.870588 0.870588 1.0" />
            </material>
        </visual>
        <visual name="robot_base_visual">
            <origin xyz="0.000000 -0.000000 0.000000" rpy="3.141592 3.141593 3.141592" />
            <geometry>
                <mesh filename="models/urdf/ur5_closed_robotiq_alpha_oriented/ur5_closed_robotiq_alpha_oriented_robot_base_visual_vis_2.dae" />
            </geometry>
            <material name="robot_base_visual_material">
                <color rgba="0.282353 0.282353 0.282353 1.0" />
            </material>
        </visual>
    </link>
    <joint type="revolute" name="joint">
        <axis xyz="0 0 1" />
        <limit effort="200.0" velocity="1.5707963705063" lower="-6.2831854820251" upper="6.2831854820251" />
        <parent link="robot_base" />
        <child link="link_respondable_respondable_respondable_respondable" />
        <origin xyz="-0.000000 -0.000000 0.008500" rpy="3.141592 3.141593 3.141592" />
    </joint>
    <link name="link_respondable_respondable_respondable_respondable">
        <inertial>
            <origin rpy="3.141592 3.141593 3.141592" xyz="-0.012312 0.000048 0.066405" />
            <inertia izz="0.09818059467752" iyz="-7.9251186174956e-05" ixx="0.095492165355254" iyy="0.10672965841326" ixz="0.0024490834762624" ixy="8.9516803607533e-05" />
            <mass value="2.5" />
        </inertial>
        <collision name="link_respondable_respondable_respondable_respondable">
            <origin xyz="-0.007178 0.000095 0.070381" rpy="3.141592 3.141593 3.141592" />
            <geometry>
                <mesh filename="models/urdf/ur5_closed_robotiq_alpha_oriented/ur5_closed_robotiq_alpha_oriented_link_respondable_respondable_respondable_respondable_coll_1.dae" />
            </geometry>
        </collision>
        <collision name="link_respondable_respondable_respondable_respondable">
            <origin xyz="-0.007178 0.000095 0.070381" rpy="3.141592 3.141593 3.141592" />
            <geometry>
                <mesh filename="models/urdf/ur5_closed_robotiq_alpha_oriented/ur5_closed_robotiq_alpha_oriented_link_respondable_respondable_respondable_respondable_coll_2.dae" />
            </geometry>
        </collision>
        <collision name="link_respondable_respondable_respondable_respondable">
            <origin xyz="-0.007178 0.000095 0.070381" rpy="3.141592 3.141593 3.141592" />
            <geometry>
                <mesh filename="models/urdf/ur5_closed_robotiq_alpha_oriented/ur5_closed_robotiq_alpha_oriented_link_respondable_respondable_respondable_respondable_coll_3.dae" />
            </geometry>
        </collision>
        <visual name="link_respondable_respondable_respondable_visual">
            <origin xyz="-0.007150 0.000000 0.070335" rpy="3.141592 3.141593 3.141592" />
            <geometry>
                <mesh filename="models/urdf/ur5_closed_robotiq_alpha_oriented/ur5_closed_robotiq_alpha_oriented_link_respondable_respondable_respondable_visual_vis_1.dae" />
            </geometry>
            <material name="link_respondable_respondable_respondable_visual_material">
                <color rgba="0.282353 0.282353 0.282353 1.0" />
            </material>
        </visual>
        <visual name="link_respondable_respondable_respondable_visual">
            <origin xyz="-0.007150 0.000000 0.070335" rpy="3.141592 3.141593 3.141592" />
            <geometry>
                <mesh filename="models/urdf/ur5_closed_robotiq_alpha_oriented/ur5_closed_robotiq_alpha_oriented_link_respondable_respondable_respondable_visual_vis_2.dae" />
            </geometry>
            <material name="link_respondable_respondable_respondable_visual_material">
                <color rgba="0.535294 0.535294 0.535294 1.0" />
            </material>
        </visual>
        <visual name="link_respondable_respondable_respondable_visual">
            <origin xyz="-0.007150 0.000000 0.070335" rpy="3.141592 3.141593 3.141592" />
            <geometry>
                <mesh filename="models/urdf/ur5_closed_robotiq_alpha_oriented/ur5_closed_robotiq_alpha_oriented_link_respondable_respondable_respondable_visual_vis_3.dae" />
            </geometry>
            <material name="link_respondable_respondable_respondable_visual_material">
                <color rgba="0.508235 0.761224 0.903529 1.0" />
            </material>
        </visual>
    </link>
    <joint type="revolute" name="joint_2">
        <axis xyz="0 0 1" />
        <limit effort="200.0" velocity="1.5707963705063" lower="-6.2831854820251" upper="6.2831854820251" />
        <parent link="link_respondable_respondable_respondable_respondable" />
        <child link="link_2_respondable_respondable_respondable_respondable" />
        <origin xyz="-0.070300 0.000000 0.066050" rpy="0.000001 -1.570796 0.000000" />
    </joint>
    <link name="link_2_respondable_respondable_respondable_respondable">
        <inertial>
            <origin rpy="-0.000000 1.570796 0.000000" xyz="0.215595 -0.000035 0.063573" />
            <inertia izz="0.067345368316432" iyz="-0.00017721757850982" ixx="0.62573305153059" iyy="0.63325135224174" ixz="-0.0052638063542259" ixy="9.2431180680848e-06" />
            <mass value="5.6999998092651" />
        </inertial>
        <collision name="link_2_respondable_respondable_respondable_respondable">
            <origin xyz="0.212550 -0.000115 0.064235" rpy="-0.000000 1.570796 0.000000" />
            <geometry>
                <mesh filename="models/urdf/ur5_closed_robotiq_alpha_oriented/ur5_closed_robotiq_alpha_oriented_link_2_respondable_respondable_respondable_respondable_coll_1.dae" />
            </geometry>
        </collision>
        <collision name="link_2_respondable_respondable_respondable_respondable">
            <origin xyz="0.212550 -0.000115 0.064235" rpy="-0.000000 1.570796 0.000000" />
            <geometry>
                <mesh filename="models/urdf/ur5_closed_robotiq_alpha_oriented/ur5_closed_robotiq_alpha_oriented_link_2_respondable_respondable_respondable_respondable_coll_2.dae" />
            </geometry>
        </collision>
        <collision name="link_2_respondable_respondable_respondable_respondable">
            <origin xyz="0.212550 -0.000115 0.064235" rpy="-0.000000 1.570796 0.000000" />
            <geometry>
                <mesh filename="models/urdf/ur5_closed_robotiq_alpha_oriented/ur5_closed_robotiq_alpha_oriented_link_2_respondable_respondable_respondable_respondable_coll_3.dae" />
            </geometry>
        </collision>
        <collision name="link_2_respondable_respondable_respondable_respondable">
            <origin xyz="0.212550 -0.000115 0.064235" rpy="-0.000000 1.570796 0.000000" />
            <geometry>
                <mesh filename="models/urdf/ur5_closed_robotiq_alpha_oriented/ur5_closed_robotiq_alpha_oriented_link_2_respondable_respondable_respondable_respondable_coll_4.dae" />
            </geometry>
        </collision>
        <collision name="link_2_respondable_respondable_respondable_respondable">
            <origin xyz="0.212550 -0.000115 0.064235" rpy="-0.000000 1.570796 0.000000" />
            <geometry>
                <mesh filename="models/urdf/ur5_closed_robotiq_alpha_oriented/ur5_closed_robotiq_alpha_oriented_link_2_respondable_respondable_respondable_respondable_coll_5.dae" />
            </geometry>
        </collision>
        <collision name="link_2_respondable_respondable_respondable_respondable">
            <origin xyz="0.212550 -0.000115 0.064235" rpy="-0.000000 1.570796 0.000000" />
            <geometry>
                <mesh filename="models/urdf/ur5_closed_robotiq_alpha_oriented/ur5_closed_robotiq_alpha_oriented_link_2_respondable_respondable_respondable_respondable_coll_6.dae" />
            </geometry>
        </collision>
        <collision name="link_2_respondable_respondable_respondable_respondable">
            <origin xyz="0.212550 -0.000115 0.064235" rpy="-0.000000 1.570796 0.000000" />
            <geometry>
                <mesh filename="models/urdf/ur5_closed_robotiq_alpha_oriented/ur5_closed_robotiq_alpha_oriented_link_2_respondable_respondable_respondable_respondable_coll_7.dae" />
            </geometry>
        </collision>
        <visual name="link_2_respondable_respondable_respondable_visual">
            <origin xyz="0.212550 -0.000000 0.064217" rpy="-0.000000 1.570796 0.000000" />
            <geometry>
                <mesh filename="models/urdf/ur5_closed_robotiq_alpha_oriented/ur5_closed_robotiq_alpha_oriented_link_2_respondable_respondable_respondable_visual_vis_1.dae" />
            </geometry>
            <material name="link_2_respondable_respondable_respondable_visual_material">
                <color rgba="0.870588 0.870588 0.870588 1.0" />
            </material>
        </visual>
        <visual name="link_2_respondable_respondable_respondable_visual">
            <origin xyz="0.212550 -0.000000 0.064217" rpy="-0.000000 1.570796 0.000000" />
            <geometry>
                <mesh filename="models/urdf/ur5_closed_robotiq_alpha_oriented/ur5_closed_robotiq_alpha_oriented_link_2_respondable_respondable_respondable_visual_vis_2.dae" />
            </geometry>
            <material name="link_2_respondable_respondable_respondable_visual_material">
                <color rgba="0.508235 0.761224 0.903529 1.0" />
            </material>
        </visual>
        <visual name="link_2_respondable_respondable_respondable_visual">
            <origin xyz="0.212550 -0.000000 0.064217" rpy="-0.000000 1.570796 0.000000" />
            <geometry>
                <mesh filename="models/urdf/ur5_closed_robotiq_alpha_oriented/ur5_closed_robotiq_alpha_oriented_link_2_respondable_respondable_respondable_visual_vis_3.dae" />
            </geometry>
            <material name="link_2_respondable_respondable_respondable_visual_material">
                <color rgba="0.535294 0.535294 0.535294 1.0" />
            </material>
        </visual>
        <visual name="link_2_respondable_respondable_respondable_visual">
            <origin xyz="0.212550 -0.000000 0.064217" rpy="-0.000000 1.570796 0.000000" />
            <geometry>
                <mesh filename="models/urdf/ur5_closed_robotiq_alpha_oriented/ur5_closed_robotiq_alpha_oriented_link_2_respondable_respondable_respondable_visual_vis_4.dae" />
            </geometry>
            <material name="link_2_respondable_respondable_respondable_visual_material">
                <color rgba="0.282353 0.282353 0.282353 1.0" />
            </material>
        </visual>
        <visual name="link_2_respondable_respondable_respondable_visual">
            <origin xyz="0.212550 -0.000000 0.064217" rpy="-0.000000 1.570796 0.000000" />
            <geometry>
                <mesh filename="models/urdf/ur5_closed_robotiq_alpha_oriented/ur5_closed_robotiq_alpha_oriented_link_2_respondable_respondable_respondable_visual_vis_5.dae" />
            </geometry>
            <material name="link_2_respondable_respondable_respondable_visual_material">
                <color rgba="0.535294 0.535294 0.535294 1.0" />
            </material>
        </visual>
        <visual name="link_2_respondable_respondable_respondable_visual">
            <origin xyz="0.212550 -0.000000 0.064217" rpy="-0.000000 1.570796 0.000000" />
            <geometry>
                <mesh filename="models/urdf/ur5_closed_robotiq_alpha_oriented/ur5_closed_robotiq_alpha_oriented_link_2_respondable_respondable_respondable_visual_vis_6.dae" />
            </geometry>
            <material name="link_2_respondable_respondable_respondable_visual_material">
                <color rgba="0.508235 0.761224 0.903529 1.0" />
            </material>
        </visual>
    </link>
    <joint type="revolute" name="joint_3">
        <axis xyz="0 0 1" />
        <limit effort="200.0" velocity="1.5707963705063" lower="-6.2831854820251" upper="6.2831854820251" />
        <parent link="link_2_respondable_respondable_respondable_respondable" />
        <child link="link_3_respondable_respondable_respondable_respondable" />
        <origin xyz="0.425100 -0.000000 0.000000" rpy="3.141593 3.141592 3.141592" />
    </joint>
    <link name="link_3_respondable_respondable_respondable_respondable">
        <inertial>
            <origin rpy="0.000000 1.570796 0.000000" xyz="0.192773 0.000015 -0.050153" />
            <inertia izz="0.035597955537677" iyz="-2.1029099787318e-05" ixx="0.4592564485459" iyy="0.46060709235019" ixz="-0.027670910392482" ixy="2.2187787147887e-06" />
            <mass value="3.9000000953674" />
        </inertial>
        <collision name="link_3_respondable_respondable_respondable_respondable">
            <origin xyz="0.186773 0.000016 -0.057847" rpy="0.000000 1.570796 0.000000" />
            <geometry>
                <mesh filename="models/urdf/ur5_closed_robotiq_alpha_oriented/ur5_closed_robotiq_alpha_oriented_link_3_respondable_respondable_respondable_respondable_coll_1.dae" />
            </geometry>
        </collision>
        <collision name="link_3_respondable_respondable_respondable_respondable">
            <origin xyz="0.186773 0.000016 -0.057847" rpy="0.000000 1.570796 0.000000" />
            <geometry>
                <mesh filename="models/urdf/ur5_closed_robotiq_alpha_oriented/ur5_closed_robotiq_alpha_oriented_link_3_respondable_respondable_respondable_respondable_coll_2.dae" />
            </geometry>
        </collision>
        <collision name="link_3_respondable_respondable_respondable_respondable">
            <origin xyz="0.186773 0.000016 -0.057847" rpy="0.000000 1.570796 0.000000" />
            <geometry>
                <mesh filename="models/urdf/ur5_closed_robotiq_alpha_oriented/ur5_closed_robotiq_alpha_oriented_link_3_respondable_respondable_respondable_respondable_coll_3.dae" />
            </geometry>
        </collision>
        <collision name="link_3_respondable_respondable_respondable_respondable">
            <origin xyz="0.186773 0.000016 -0.057847" rpy="0.000000 1.570796 0.000000" />
            <geometry>
                <mesh filename="models/urdf/ur5_closed_robotiq_alpha_oriented/ur5_closed_robotiq_alpha_oriented_link_3_respondable_respondable_respondable_respondable_coll_4.dae" />
            </geometry>
        </collision>
        <collision name="link_3_respondable_respondable_respondable_respondable">
            <origin xyz="0.186773 0.000016 -0.057847" rpy="0.000000 1.570796 0.000000" />
            <geometry>
                <mesh filename="models/urdf/ur5_closed_robotiq_alpha_oriented/ur5_closed_robotiq_alpha_oriented_link_3_respondable_respondable_respondable_respondable_coll_5.dae" />
            </geometry>
        </collision>
        <visual name="link_3_respondable_respondable_respondable_visual">
            <origin xyz="0.186650 -0.000000 -0.057850" rpy="0.000000 1.570796 0.000000" />
            <geometry>
                <mesh filename="models/urdf/ur5_closed_robotiq_alpha_oriented/ur5_closed_robotiq_alpha_oriented_link_3_respondable_respondable_respondable_visual_vis_1.dae" />
            </geometry>
            <material name="link_3_respondable_respondable_respondable_visual_material">
                <color rgba="0.870588 0.870588 0.870588 1.0" />
            </material>
        </visual>
        <visual name="link_3_respondable_respondable_respondable_visual">
            <origin xyz="0.186650 -0.000000 -0.057850" rpy="0.000000 1.570796 0.000000" />
            <geometry>
                <mesh filename="models/urdf/ur5_closed_robotiq_alpha_oriented/ur5_closed_robotiq_alpha_oriented_link_3_respondable_respondable_respondable_visual_vis_2.dae" />
            </geometry>
            <material name="link_3_respondable_respondable_respondable_visual_material">
                <color rgba="0.535294 0.535294 0.535294 1.0" />
            </material>
        </visual>
        <visual name="link_3_respondable_respondable_respondable_visual">
            <origin xyz="0.186650 -0.000000 -0.057850" rpy="0.000000 1.570796 0.000000" />
            <geometry>
                <mesh filename="models/urdf/ur5_closed_robotiq_alpha_oriented/ur5_closed_robotiq_alpha_oriented_link_3_respondable_respondable_respondable_visual_vis_3.dae" />
            </geometry>
            <material name="link_3_respondable_respondable_respondable_visual_material">
                <color rgba="0.508235 0.761224 0.903529 1.0" />
            </material>
        </visual>
        <visual name="link_3_respondable_respondable_respondable_visual">
            <origin xyz="0.186650 -0.000000 -0.057850" rpy="0.000000 1.570796 0.000000" />
            <geometry>
                <mesh filename="models/urdf/ur5_closed_robotiq_alpha_oriented/ur5_closed_robotiq_alpha_oriented_link_3_respondable_respondable_respondable_visual_vis_4.dae" />
            </geometry>
            <material name="link_3_respondable_respondable_respondable_visual_material">
                <color rgba="0.282353 0.282353 0.282353 1.0" />
            </material>
        </visual>
        <visual name="link_3_respondable_respondable_respondable_visual">
            <origin xyz="0.186650 -0.000000 -0.057850" rpy="0.000000 1.570796 0.000000" />
            <geometry>
                <mesh filename="models/urdf/ur5_closed_robotiq_alpha_oriented/ur5_closed_robotiq_alpha_oriented_link_3_respondable_respondable_respondable_visual_vis_5.dae" />
            </geometry>
            <material name="link_3_respondable_respondable_respondable_visual_material">
                <color rgba="0.535294 0.535294 0.535294 1.0" />
            </material>
        </visual>
    </link>
    <joint type="revolute" name="joint_4">
        <axis xyz="0 0 1" />
        <limit effort="200.0" velocity="1.5707963705063" lower="-6.2831854820251" upper="6.2831854820251" />
        <parent link="link_3_respondable_respondable_respondable_respondable" />
        <child link="link_4_respondable_respondable_respondable_respondable" />
        <origin xyz="0.392150 -0.000000 0.000000" rpy="3.141593 3.141592 3.141592" />
    </joint>
    <link name="link_4_respondable_respondable_respondable_respondable">
        <inertial>
            <origin rpy="0.000000 1.570796 0.000000" xyz="-0.005517 -0.000003 0.030943" />
            <inertia izz="0.087106483494915" iyz="-1.791527123899e-05" ixx="0.10017005794782" iyy="0.11466452218562" ixz="-0.0020900872562349" ixy="3.1976010243315e-06" />
            <mass value="2.5" />
        </inertial>
        <collision name="link_4_respondable_respondable_respondable_respondable">
            <origin xyz="-0.007501 -0.000045 0.032830" rpy="0.000000 1.570796 0.000000" />
            <geometry>
                <mesh filename="models/urdf/ur5_closed_robotiq_alpha_oriented/ur5_closed_robotiq_alpha_oriented_link_4_respondable_respondable_respondable_respondable_coll_1.dae" />
            </geometry>
        </collision>
        <collision name="link_4_respondable_respondable_respondable_respondable">
            <origin xyz="-0.007501 -0.000045 0.032830" rpy="0.000000 1.570796 0.000000" />
            <geometry>
                <mesh filename="models/urdf/ur5_closed_robotiq_alpha_oriented/ur5_closed_robotiq_alpha_oriented_link_4_respondable_respondable_respondable_respondable_coll_2.dae" />
            </geometry>
        </collision>
        <collision name="link_4_respondable_respondable_respondable_respondable">
            <origin xyz="-0.007501 -0.000045 0.032830" rpy="0.000000 1.570796 0.000000" />
            <geometry>
                <mesh filename="models/urdf/ur5_closed_robotiq_alpha_oriented/ur5_closed_robotiq_alpha_oriented_link_4_respondable_respondable_respondable_respondable_coll_3.dae" />
            </geometry>
        </collision>
        <visual name="link_4_respondable_respondable_respondable_visual">
            <origin xyz="-0.007500 0.000000 0.032800" rpy="0.000000 1.570796 0.000000" />
            <geometry>
                <mesh filename="models/urdf/ur5_closed_robotiq_alpha_oriented/ur5_closed_robotiq_alpha_oriented_link_4_respondable_respondable_respondable_visual_vis_1.dae" />
            </geometry>
            <material name="link_4_respondable_respondable_respondable_visual_material">
                <color rgba="0.282353 0.282353 0.282353 1.0" />
            </material>
        </visual>
        <visual name="link_4_respondable_respondable_respondable_visual">
            <origin xyz="-0.007500 0.000000 0.032800" rpy="0.000000 1.570796 0.000000" />
            <geometry>
                <mesh filename="models/urdf/ur5_closed_robotiq_alpha_oriented/ur5_closed_robotiq_alpha_oriented_link_4_respondable_respondable_respondable_visual_vis_2.dae" />
            </geometry>
            <material name="link_4_respondable_respondable_respondable_visual_material">
                <color rgba="0.535294 0.535294 0.535294 1.0" />
            </material>
        </visual>
        <visual name="link_4_respondable_respondable_respondable_visual">
            <origin xyz="-0.007500 0.000000 0.032800" rpy="0.000000 1.570796 0.000000" />
            <geometry>
                <mesh filename="models/urdf/ur5_closed_robotiq_alpha_oriented/ur5_closed_robotiq_alpha_oriented_link_4_respondable_respondable_respondable_visual_vis_3.dae" />
            </geometry>
            <material name="link_4_respondable_respondable_respondable_visual_material">
                <color rgba="0.508235 0.761224 0.903529 1.0" />
            </material>
        </visual>
    </link>
    <joint type="revolute" name="joint_5">
        <axis xyz="0 0 1" />
        <limit effort="200.0" velocity="1.5707963705063" lower="-6.2831854820251" upper="6.2831854820251" />
        <parent link="link_4_respondable_respondable_respondable_respondable" />
        <child link="link_5_respondable_respondable_respondable_respondable" />
        <origin xyz="0.045575 -0.000000 0.039700" rpy="2.571178 1.570799 2.571178" />
    </joint>
    <link name="link_5_respondable_respondable_respondable_respondable">
        <inertial>
            <origin rpy="3.141592 3.141593 3.141592" xyz="0.002100 0.000002 0.040669" />
            <inertia izz="0.1041509279002" iyz="3.8714712477568e-06" ixx="0.08179215416809" iyy="0.11739579576874" ixz="-0.00073245390311674" ixy="-1.5531769026879e-05" />
            <mass value="2.5" />
        </inertial>
        <collision name="link_5_respondable_respondable_respondable_respondable">
            <origin xyz="0.003601 0.000045 0.042305" rpy="3.141592 3.141593 3.141592" />
            <geometry>
                <mesh filename="models/urdf/ur5_closed_robotiq_alpha_oriented/ur5_closed_robotiq_alpha_oriented_link_5_respondable_respondable_respondable_respondable_coll_1.dae" />
            </geometry>
        </collision>
        <collision name="link_5_respondable_respondable_respondable_respondable">
            <origin xyz="0.003601 0.000045 0.042305" rpy="3.141592 3.141593 3.141592" />
            <geometry>
                <mesh filename="models/urdf/ur5_closed_robotiq_alpha_oriented/ur5_closed_robotiq_alpha_oriented_link_5_respondable_respondable_respondable_respondable_coll_2.dae" />
            </geometry>
        </collision>
        <collision name="link_5_respondable_respondable_respondable_respondable">
            <origin xyz="0.003601 0.000045 0.042305" rpy="3.141592 3.141593 3.141592" />
            <geometry>
                <mesh filename="models/urdf/ur5_closed_robotiq_alpha_oriented/ur5_closed_robotiq_alpha_oriented_link_5_respondable_respondable_respondable_respondable_coll_3.dae" />
            </geometry>
        </collision>
        <visual name="link_5_respondable_respondable_respondable_visual">
            <origin xyz="0.003600 -0.000000 0.042275" rpy="3.141592 3.141593 3.141592" />
            <geometry>
                <mesh filename="models/urdf/ur5_closed_robotiq_alpha_oriented/ur5_closed_robotiq_alpha_oriented_link_5_respondable_respondable_respondable_visual_vis_1.dae" />
            </geometry>
            <material name="link_5_respondable_respondable_respondable_visual_material">
                <color rgba="0.535294 0.535294 0.535294 1.0" />
            </material>
        </visual>
        <visual name="link_5_respondable_respondable_respondable_visual">
            <origin xyz="0.003600 -0.000000 0.042275" rpy="3.141592 3.141593 3.141592" />
            <geometry>
                <mesh filename="models/urdf/ur5_closed_robotiq_alpha_oriented/ur5_closed_robotiq_alpha_oriented_link_5_respondable_respondable_respondable_visual_vis_2.dae" />
            </geometry>
            <material name="link_5_respondable_respondable_respondable_visual_material">
                <color rgba="0.508235 0.761224 0.903529 1.0" />
            </material>
        </visual>
        <visual name="link_5_respondable_respondable_respondable_visual">
            <origin xyz="0.003600 -0.000000 0.042275" rpy="3.141592 3.141593 3.141592" />
            <geometry>
                <mesh filename="models/urdf/ur5_closed_robotiq_alpha_oriented/ur5_closed_robotiq_alpha_oriented_link_5_respondable_respondable_respondable_visual_vis_3.dae" />
            </geometry>
            <material name="link_5_respondable_respondable_respondable_visual_material">
                <color rgba="0.282353 0.282353 0.282353 1.0" />
            </material>
        </visual>
        <visual name="link_5_respondable_respondable_respondable_visual">
            <origin xyz="0.003600 -0.000000 0.042275" rpy="3.141592 3.141593 3.141592" />
            <geometry>
                <mesh filename="models/urdf/ur5_closed_robotiq_alpha_oriented/ur5_closed_robotiq_alpha_oriented_link_5_respondable_respondable_respondable_visual_vis_4.dae" />
            </geometry>
            <material name="link_5_respondable_respondable_respondable_visual_material">
                <color rgba="0.282353 0.282353 0.282353 1.0" />
            </material>
        </visual>
    </link>
    <joint type="revolute" name="joint_6">
        <axis xyz="0 0 1" />
        <limit effort="200.0" velocity="1.5707963705063" lower="-6.2831854820251" upper="6.2831854820251" />
        <parent link="link_5_respondable_respondable_respondable_respondable" />
        <child link="link_6_respondable_respondable_respondable_respondable" />
        <origin xyz="0.014425 -0.000000 0.049175" rpy="-3.141592 4.712385 -3.141592" />
    </joint>
    <link name="link_6_respondable_respondable_respondable_respondable">
        <inertial>
            <origin rpy="-3.141593 3.141593 3.141592" xyz="0.000000 -0.000000 0.076675" />
            <inertia izz="0.010054638677955" iyz="6.1857946146313e-26" ixx="0.0058406852103875" iyy="0.0058406852103875" ixz="-6.1857946188379e-26" ixy="-2.7147808519794e-48" />
            <mass value="0.69999998807907" />
        </inertial>
        <collision name="link_6_respondable_respondable_respondable_respondable">
            <origin xyz="0.000000 -0.000000 0.076675" rpy="-3.141593 3.141593 3.141592" />
            <geometry>
                <cylinder length="0.025500684976578" radius="0.036602452397346" />
            </geometry>
        </collision>
        <visual name="link_6_respondable_respondable_respondable_visual">
            <origin xyz="0.003860 -0.000000 0.080425" rpy="0.000001 1.570796 0.000000" />
            <geometry>
                <mesh filename="models/urdf/ur5_closed_robotiq_alpha_oriented/ur5_closed_robotiq_alpha_oriented_link_6_respondable_respondable_respondable_visual_vis_1.dae" />
            </geometry>
            <material name="link_6_respondable_respondable_respondable_visual_material">
                <color rgba="0.870588 0.870588 0.870588 1.0" />
            </material>
        </visual>
    </link>
    <joint type="revolute" name="joint_6_2">
        <axis xyz="0 0 1" />
        <limit effort="200.0" velocity="1.5707963705063" lower="-6.2831854820251" upper="6.2831854820251" />
        <parent link="link_6_respondable_respondable_respondable_respondable" />
        <child link="robotiq_base_respondable_respondable_respondable_respondable" />
        <origin xyz="0.014425 0.000000 0.049175" rpy="1.569705 4.712384 -1.569705" />
    </joint>
    <link name="robotiq_base_respondable_respondable_respondable_respondable">
        <inertial>
            <origin rpy="1.570796 3.141592 -3.141591" xyz="0.043899 0.008350 0.012000" />
            <inertia izz="0.00072521695233332" iyz="-2.9619775669806e-11" ixx="0.00070222511049253" iyy="0.00024588701243668" ixz="3.003181387601e-05" ixy="-3.0779821976413e-10" />
            <mass value="0.5" />
        </inertial>
        <collision name="robotiq_base_respondable_respondable_respondable_respondable">
            <origin xyz="0.030000 0.010000 0.012000" rpy="1.570796 3.141592 -3.141591" />
            <geometry>
                <box size="0.017463 0.050800 0.057938" />
            </geometry>
        </collision>
        <collision name="robotiq_base_respondable_respondable_respondable_respondable">
            <origin xyz="0.083032 -0.004681 0.012000" rpy="3.141592 3.141592 -3.141591" />
            <geometry>
                <box size="0.040000 0.020600 0.040000" />
            </geometry>
        </collision>
        <collision name="robotiq_base_respondable_respondable_respondable_respondable">
            <origin xyz="0.041272 0.009924 0.012000" rpy="-0.000001 3.141592 -3.141591" />
            <geometry>
                <box size="0.030480 0.051435 0.139700" />
            </geometry>
        </collision>
        <visual name="robotiq_base_respondable_respondable_respondable_visual">
            <origin xyz="0.062151 0.010000 0.012000" rpy="-0.000005 1.570796 0.000000" />
            <geometry>
                <mesh filename="models/urdf/ur5_closed_robotiq_alpha_oriented/ur5_closed_robotiq_alpha_oriented_robotiq_base_respondable_respondable_respondable_visual_vis_1.dae" />
            </geometry>
            <material name="robotiq_base_respondable_respondable_respondable_visual_material">
                <color rgba="0.282317 0.282389 0.282389 1.0" />
            </material>
        </visual>
        <visual name="robotiq_base_respondable_respondable_respondable_visual">
            <origin xyz="0.062151 0.010000 0.012000" rpy="-0.000005 1.570796 0.000000" />
            <geometry>
                <mesh filename="models/urdf/ur5_closed_robotiq_alpha_oriented/ur5_closed_robotiq_alpha_oriented_robotiq_base_respondable_respondable_respondable_visual_vis_2.dae" />
            </geometry>
            <material name="robotiq_base_respondable_respondable_respondable_visual_material">
                <color rgba="1.000000 1.000000 1.000000 1.0" />
            </material>
        </visual>
    </link>
    <joint type="revolute" name="joint_6_3">
        <axis xyz="0 0 1" />
        <limit effort="200.0" velocity="1.5707963705063" lower="-6.2831854820251" upper="6.2831854820251" />
        <parent link="robotiq_base_respondable_respondable_respondable_respondable" />
        <child link="alpha_link_respondable_respondable" />
        <origin xyz="0.030000 0.010000 0.012000" rpy="1.570818 3.141589 -1.570788" />
    </joint>
    <link name="alpha_link_respondable_respondable">
        <collision name="alpha_link_respondable_respondable">
            <origin xyz="-0.010492 -0.001728 -0.122145" rpy="-3.141593 -1.570796 0.000000" />
            <geometry>
                <mesh filename="models/urdf/ur5_closed_robotiq_alpha_oriented/ur5_closed_robotiq_alpha_oriented_alpha_link_respondable_respondable_coll_1.dae" />
            </geometry>
        </collision>
        <visual name="alpha_dynamic">
            <origin xyz="-0.010492 -0.001728 -0.122145" rpy="-3.141593 -1.570796 0.000000" />
            <geometry>
                <mesh filename="models/urdf/ur5_closed_robotiq_alpha_oriented/ur5_closed_robotiq_alpha_oriented_alpha_dynamic_vis_1.dae" />
            </geometry>
            <material name="alpha_dynamic_material">
                <color rgba="0.600000 0.600000 0.600000 1.0" />
            </material>
        </visual>
    </link>
    <joint type="revolute" name="Rjoint1">
        <axis xyz="0 0 1" />
        <limit effort="1.0" velocity="0.69813168048859" lower="0.0" upper="0.78539818525314" />
        <parent link="robotiq_base_respondable_respondable_respondable_respondable" />
        <child link="Rfinger_respondable_respondable_respondable_respondable" />
        <origin xyz="0.074600 -0.004681 -0.000738" rpy="-1.365597 1.570798 -2.936391" />
    </joint>
    <link name="Rfinger_respondable_respondable_respondable_respondable">
        <inertial>
            <origin rpy="1.570973 3.138398 -0.197315" xyz="0.005488 0.027095 -0.000010" />
            <inertia izz="7.6569405819033e-06" iyz="2.3306575187576e-20" ixx="3.4844272621657e-05" iyy="2.9984947551464e-05" ixz="2.0286971704159e-20" ixy="3.0270197699468e-21" />
            <mass value="0.10000000149012" />
        </inertial>
        <collision name="Rfinger_respondable_respondable_respondable_respondable">
            <origin xyz="0.005488 0.027095 -0.000010" rpy="1.570973 3.138398 -0.197315" />
            <geometry>
                <box size="0.015803 0.033427 0.071444" />
            </geometry>
        </collision>
        <visual name="Rfinger_respondable_respondable_respondable_visual">
            <origin xyz="0.005488 0.027095 -0.000010" rpy="1.570973 3.138398 -0.197315" />
            <geometry>
                <mesh filename="models/urdf/ur5_closed_robotiq_alpha_oriented/ur5_closed_robotiq_alpha_oriented_Rfinger_respondable_respondable_respondable_visual_vis_1.dae" />
            </geometry>
            <material name="Rfinger_respondable_respondable_respondable_visual_material">
                <color rgba="0.282317 0.282389 0.282389 1.0" />
            </material>
        </visual>
        <visual name="Rfinger_respondable_respondable_respondable_visual">
            <origin xyz="0.005488 0.027095 -0.000010" rpy="1.570973 3.138398 -0.197315" />
            <geometry>
                <mesh filename="models/urdf/ur5_closed_robotiq_alpha_oriented/ur5_closed_robotiq_alpha_oriented_Rfinger_respondable_respondable_respondable_visual_vis_2.dae" />
            </geometry>
            <material name="Rfinger_respondable_respondable_respondable_visual_material">
                <color rgba="0.837524 0.970755 1.000000 1.0" />
            </material>
        </visual>
    </link>
    <joint type="continuous" name="Rjoint2">
        <axis xyz="0 0 1" />
        <parent link="Rfinger_respondable_respondable_respondable_respondable" />
        <child link="RfingerTip_respondable_respondable_respondable_respondable" />
        <origin xyz="0.011178 0.055908 -0.000005" rpy="3.141588 3.141599 -2.617992" />
    </joint>
    <link name="RfingerTip_respondable_respondable_respondable_respondable">
        <inertial>
            <origin rpy="1.570791 3.141584 2.618125" xyz="0.011429 0.016336 0.000003" />
            <inertia izz="1.0653877098426e-05" iyz="3.0402031090976e-09" ixx="3.0898972527854e-05" iyy="3.3094096464058e-05" ixz="9.351945982435e-06" ixy="-1.5997928581692e-09" />
            <mass value="0.10000000149012" />
        </inertial>
        <collision name="RfingerTip_respondable_respondable_respondable_respondable">
            <origin xyz="0.011082 0.025433 0.000005" rpy="1.570791 3.141584 2.618125" />
            <geometry>
                <box size="0.009509 0.025404 0.036832" />
            </geometry>
        </collision>
        <collision name="RfingerTip_respondable_respondable_respondable_respondable">
            <origin xyz="0.014108 0.016940 0.000003" rpy="-1.570934 3.141603 -0.523468" />
            <geometry>
                <box size="0.008509 0.014223 0.025144" />
            </geometry>
        </collision>
        <collision name="RfingerTip_respondable_respondable_respondable_respondable">
            <origin xyz="0.009800 -0.010308 0.000000" rpy="2.704256 1.571046 -1.484400" />
            <geometry>
                <box size="0.011078 0.012672 0.022135" />
            </geometry>
        </collision>
        <visual name="RfingerTip_respondable_respondable_respondable_visual">
            <origin xyz="0.015282 0.010304 0.000004" rpy="1.570922 3.141584 2.618151" />
            <geometry>
                <mesh filename="models/urdf/ur5_closed_robotiq_alpha_oriented/ur5_closed_robotiq_alpha_oriented_RfingerTip_respondable_respondable_respondable_visual_vis_1.dae" />
            </geometry>
            <material name="RfingerTip_respondable_respondable_respondable_visual_material">
                <color rgba="0.282317 0.282389 0.282389 1.0" />
            </material>
        </visual>
        <visual name="RfingerTip_respondable_respondable_respondable_visual">
            <origin xyz="0.015282 0.010304 0.000004" rpy="1.570922 3.141584 2.618151" />
            <geometry>
                <mesh filename="models/urdf/ur5_closed_robotiq_alpha_oriented/ur5_closed_robotiq_alpha_oriented_RfingerTip_respondable_respondable_respondable_visual_vis_2.dae" />
            </geometry>
            <material name="RfingerTip_respondable_respondable_respondable_visual_material">
                <color rgba="0.305882 0.305882 0.305882 1.0" />
            </material>
        </visual>
    </link>
    <joint type="continuous" name="RactiveJoint">
        <axis xyz="0 0 1" />
        <parent link="robotiq_base_respondable_respondable_respondable_respondable" />
        <child link="RauxLink1Visible_visual_visual_visual_visual" />
        <origin xyz="0.067942 -0.004681 -0.018601" rpy="-1.365597 1.570798 -2.936391" />
    </joint>
    <link name="RauxLink1Visible_visual_visual_visual_visual">
        <visual name="RauxLink1Visible_visual_visual_visual_visual">
            <origin xyz="0.014963 -0.001623 0.000001" rpy="-1.570931 3.141677 -1.674482" />
            <geometry>
                <mesh filename="models/urdf/ur5_closed_robotiq_alpha_oriented/ur5_closed_robotiq_alpha_oriented_RauxLink1Visible_visual_visual_visual_visual_vis_1.dae" />
            </geometry>
            <material name="RauxLink1Visible_visual_visual_visual_visual_material">
                <color rgba="0.282317 0.282389 0.282389 1.0" />
            </material>
        </visual>
        <visual name="RauxLink1Visible_visual_visual_visual_visual">
            <origin xyz="0.014963 -0.001623 0.000001" rpy="-1.570931 3.141677 -1.674482" />
            <geometry>
                <mesh filename="models/urdf/ur5_closed_robotiq_alpha_oriented/ur5_closed_robotiq_alpha_oriented_RauxLink1Visible_visual_visual_visual_visual_vis_2.dae" />
            </geometry>
            <material name="RauxLink1Visible_visual_visual_visual_visual_material">
                <color rgba="0.837524 0.970755 1.000000 1.0" />
            </material>
        </visual>
    </link>
    <joint type="continuous" name="RauxJoint2">
        <axis xyz="0 0 1" />
        <parent link="RauxLink1Visible_visual_visual_visual_visual" />
        <child link="RauxLink2Visible_visual_visual_visual_visual" />
        <origin xyz="0.031465 -0.004244 -0.000000" rpy="-3.141592 3.141593 -3.141592" />
    </joint>
    <link name="RauxLink2Visible_visual_visual_visual_visual">
        <visual name="RauxLink2Visible_visual_visual_visual_visual">
            <origin xyz="0.003104 0.023609 0.000000" rpy="-1.570795 3.141585 -0.130688" />
            <geometry>
                <mesh filename="models/urdf/ur5_closed_robotiq_alpha_oriented/ur5_closed_robotiq_alpha_oriented_RauxLink2Visible_visual_visual_visual_visual_vis_1.dae" />
            </geometry>
            <material name="RauxLink2Visible_visual_visual_visual_visual_material">
                <color rgba="0.282317 0.282389 0.282389 1.0" />
            </material>
        </visual>
        <visual name="RauxLink2Visible_visual_visual_visual_visual">
            <origin xyz="0.003104 0.023609 0.000000" rpy="-1.570795 3.141585 -0.130688" />
            <geometry>
                <mesh filename="models/urdf/ur5_closed_robotiq_alpha_oriented/ur5_closed_robotiq_alpha_oriented_RauxLink2Visible_visual_visual_visual_visual_vis_2.dae" />
            </geometry>
            <material name="RauxLink2Visible_visual_visual_visual_visual_material">
                <color rgba="0.837524 0.970755 1.000000 1.0" />
            </material>
        </visual>
    </link>
    <joint type="revolute" name="Ljoint1">
        <axis xyz="0 0 1" />
        <limit effort="1.0" velocity="0.69813168048859" lower="0.0" upper="0.78539818525314" />
        <parent link="robotiq_base_respondable_respondable_respondable_respondable" />
        <child link="Lfinger_respondable_respondable_respondable_respondable" />
        <origin xyz="0.074600 -0.004681 0.024736" rpy="-1.570793 -1.570796 0.000000" />
    </joint>
    <link name="Lfinger_respondable_respondable_respondable_respondable">
        <inertial>
            <origin rpy="1.570973 3.138400 -0.197320" xyz="0.005488 0.027096 -0.000000" />
            <inertia izz="7.6569405819033e-06" iyz="2.5231646246181e-20" ixx="3.4844272621657e-05" iyy="2.9984947551464e-05" ixz="1.7991877794729e-20" ixy="4.0558578097857e-21" />
            <mass value="0.10000000149012" />
        </inertial>
        <collision name="Lfinger_respondable_respondable_respondable_respondable">
            <origin xyz="0.005488 0.027096 -0.000000" rpy="1.570973 3.138400 -0.197320" />
            <geometry>
                <box size="0.015803 0.033427 0.071444" />
            </geometry>
        </collision>
        <visual name="Lfinger_respondable_respondable_respondable_visual">
            <origin xyz="0.005488 0.027096 -0.000000" rpy="1.570973 3.138400 -0.197320" />
            <geometry>
                <mesh filename="models/urdf/ur5_closed_robotiq_alpha_oriented/ur5_closed_robotiq_alpha_oriented_Lfinger_respondable_respondable_respondable_visual_vis_1.dae" />
            </geometry>
            <material name="Lfinger_respondable_respondable_respondable_visual_material">
                <color rgba="0.282317 0.282389 0.282389 1.0" />
            </material>
        </visual>
        <visual name="Lfinger_respondable_respondable_respondable_visual">
            <origin xyz="0.005488 0.027096 -0.000000" rpy="1.570973 3.138400 -0.197320" />
            <geometry>
                <mesh filename="models/urdf/ur5_closed_robotiq_alpha_oriented/ur5_closed_robotiq_alpha_oriented_Lfinger_respondable_respondable_respondable_visual_vis_2.dae" />
            </geometry>
            <material name="Lfinger_respondable_respondable_respondable_visual_material">
                <color rgba="0.837524 0.970755 1.000000 1.0" />
            </material>
        </visual>
    </link>
    <joint type="continuous" name="Ljoint2">
        <axis xyz="0 0 1" />
        <parent link="Lfinger_respondable_respondable_respondable_respondable" />
        <child link="LfingerTip_respondable_respondable_respondable_respondable" />
        <origin xyz="0.011178 0.055909 0.000005" rpy="3.141589 3.141598 -2.617995" />
    </joint>
    <link name="LfingerTip_respondable_respondable_respondable_respondable">
        <inertial>
            <origin rpy="1.570803 3.141585 2.617862" xyz="0.011426 0.016336 -0.000007" />
            <inertia izz="1.0653864139997e-05" iyz="3.0402050629679e-09" ixx="3.0898985486283e-05" iyy="3.3094096464058e-05" ixz="9.3519319562104e-06" ixy="-1.5997909493312e-09" />
            <mass value="0.10000000149012" />
        </inertial>
        <collision name="LfingerTip_respondable_respondable_respondable_respondable">
            <origin xyz="0.011081 0.025434 -0.000005" rpy="1.570803 3.141585 2.617862" />
            <geometry>
                <box size="0.009509 0.025404 0.036832" />
            </geometry>
        </collision>
        <collision name="LfingerTip_respondable_respondable_respondable_respondable">
            <origin xyz="0.014105 0.016940 -0.000006" rpy="-1.570946 3.141602 -0.523731" />
            <geometry>
                <box size="0.008509 0.014223 0.025144" />
            </geometry>
        </collision>
        <collision name="LfingerTip_respondable_respondable_respondable_respondable">
            <origin xyz="0.009790 -0.010306 -0.000010" rpy="2.674078 1.571055 -1.514842" />
            <geometry>
                <box size="0.011078 0.012672 0.022135" />
            </geometry>
        </collision>
        <visual name="LfingerTip_respondable_respondable_respondable_visual">
            <origin xyz="0.015277 0.010302 -0.000006" rpy="1.570934 3.141585 2.617887" />
            <geometry>
                <mesh filename="models/urdf/ur5_closed_robotiq_alpha_oriented/ur5_closed_robotiq_alpha_oriented_LfingerTip_respondable_respondable_respondable_visual_vis_1.dae" />
            </geometry>
            <material name="LfingerTip_respondable_respondable_respondable_visual_material">
                <color rgba="0.282317 0.282389 0.282389 1.0" />
            </material>
        </visual>
        <visual name="LfingerTip_respondable_respondable_respondable_visual">
            <origin xyz="0.015277 0.010302 -0.000006" rpy="1.570934 3.141585 2.617887" />
            <geometry>
                <mesh filename="models/urdf/ur5_closed_robotiq_alpha_oriented/ur5_closed_robotiq_alpha_oriented_LfingerTip_respondable_respondable_respondable_visual_vis_2.dae" />
            </geometry>
            <material name="LfingerTip_respondable_respondable_respondable_visual_material">
                <color rgba="0.305882 0.305882 0.305882 1.0" />
            </material>
        </visual>
    </link>
    <joint type="continuous" name="LactiveJoint">
        <axis xyz="0 0 1" />
        <parent link="robotiq_base_respondable_respondable_respondable_respondable" />
        <child link="LauxLink1Visible_visual_visual_visual_visual" />
        <origin xyz="0.067942 -0.004681 0.042599" rpy="-1.570793 -1.570796 0.000000" />
    </joint>
    <link name="LauxLink1Visible_visual_visual_visual_visual">
        <visual name="LauxLink1Visible_visual_visual_visual_visual">
            <origin xyz="0.014963 -0.001623 0.000001" rpy="-1.570931 3.141677 -1.674482" />
            <geometry>
                <mesh filename="models/urdf/ur5_closed_robotiq_alpha_oriented/ur5_closed_robotiq_alpha_oriented_LauxLink1Visible_visual_visual_visual_visual_vis_1.dae" />
            </geometry>
            <material name="LauxLink1Visible_visual_visual_visual_visual_material">
                <color rgba="0.282317 0.282389 0.282389 1.0" />
            </material>
        </visual>
        <visual name="LauxLink1Visible_visual_visual_visual_visual">
            <origin xyz="0.014963 -0.001623 0.000001" rpy="-1.570931 3.141677 -1.674482" />
            <geometry>
                <mesh filename="models/urdf/ur5_closed_robotiq_alpha_oriented/ur5_closed_robotiq_alpha_oriented_LauxLink1Visible_visual_visual_visual_visual_vis_2.dae" />
            </geometry>
            <material name="LauxLink1Visible_visual_visual_visual_visual_material">
                <color rgba="0.837524 0.970755 1.000000 1.0" />
            </material>
        </visual>
    </link>
    <joint type="continuous" name="LauxJoint2">
        <axis xyz="0 0 1" />
        <parent link="LauxLink1Visible_visual_visual_visual_visual" />
        <child link="LauxLink2Visible_visual_visual_visual_visual" />
        <origin xyz="0.031465 -0.004244 0.000000" rpy="3.141592 3.141593 -3.141592" />
    </joint>
    <link name="LauxLink2Visible_visual_visual_visual_visual">
        <visual name="LauxLink2Visible_visual_visual_visual_visual">
            <origin xyz="0.003104 0.023609 -0.000000" rpy="-1.570795 3.141585 -0.130688" />
            <geometry>
                <mesh filename="models/urdf/ur5_closed_robotiq_alpha_oriented/ur5_closed_robotiq_alpha_oriented_LauxLink2Visible_visual_visual_visual_visual_vis_1.dae" />
            </geometry>
            <material name="LauxLink2Visible_visual_visual_visual_visual_material">
                <color rgba="0.282317 0.282389 0.282389 1.0" />
            </material>
        </visual>
        <visual name="LauxLink2Visible_visual_visual_visual_visual">
            <origin xyz="0.003104 0.023609 -0.000000" rpy="-1.570795 3.141585 -0.130688" />
            <geometry>
                <mesh filename="models/urdf/ur5_closed_robotiq_alpha_oriented/ur5_closed_robotiq_alpha_oriented_LauxLink2Visible_visual_visual_visual_visual_vis_2.dae" />
            </geometry>
            <material name="LauxLink2Visible_visual_visual_visual_visual_material">
                <color rgba="0.837524 0.970755 1.000000 1.0" />
            </material>
        </visual>
    </link>
</robot>
